{"trial_id": "1", "hyperparameters": {"space": [{"class_name": "Choice", "config": {"name": "learning_rate", "default": 0.01, "conditions": [], "values": [0.01, 0.001, 0.0001], "ordered": true}}], "values": {"learning_rate": 0.001}}, "metrics": {"metrics": {}}, "score": null, "best_step": 0, "status": "FAILED", "message": "Traceback (most recent call last):\n  File \"c:\\Users\\daled\\anaconda3\\envs\\learn-env\\lib\\site-packages\\keras_tuner\\src\\engine\\base_tuner.py\", line 274, in _try_run_and_update_trial\n    self._run_and_update_trial(trial, *fit_args, **fit_kwargs)\n  File \"c:\\Users\\daled\\anaconda3\\envs\\learn-env\\lib\\site-packages\\keras_tuner\\src\\engine\\base_tuner.py\", line 239, in _run_and_update_trial\n    results = self.run_trial(trial, *fit_args, **fit_kwargs)\n  File \"c:\\Users\\daled\\anaconda3\\envs\\learn-env\\lib\\site-packages\\keras_tuner\\src\\engine\\tuner.py\", line 314, in run_trial\n    obj_value = self._build_and_fit_model(trial, *args, **copied_kwargs)\n  File \"c:\\Users\\daled\\anaconda3\\envs\\learn-env\\lib\\site-packages\\keras_tuner\\src\\engine\\tuner.py\", line 233, in _build_and_fit_model\n    results = self.hypermodel.fit(hp, model, *args, **kwargs)\n  File \"c:\\Users\\daled\\anaconda3\\envs\\learn-env\\lib\\site-packages\\keras_tuner\\src\\engine\\hypermodel.py\", line 149, in fit\n    return model.fit(*args, **kwargs)\n  File \"c:\\Users\\daled\\anaconda3\\envs\\learn-env\\lib\\site-packages\\keras\\utils\\traceback_utils.py\", line 67, in error_handler\n    raise e.with_traceback(filtered_tb) from None\n  File \"c:\\Users\\daled\\anaconda3\\envs\\learn-env\\lib\\site-packages\\tensorflow\\python\\framework\\func_graph.py\", line 1147, in autograph_handler\n    raise e.ag_error_metadata.to_exception(e)\nValueError: in user code:\n\n    File \"c:\\Users\\daled\\anaconda3\\envs\\learn-env\\lib\\site-packages\\keras\\engine\\training.py\", line 1021, in train_function  *\n        return step_function(self, iterator)\n    File \"c:\\Users\\daled\\anaconda3\\envs\\learn-env\\lib\\site-packages\\keras\\engine\\training.py\", line 1010, in step_function  **\n        outputs = model.distribute_strategy.run(run_step, args=(data,))\n    File \"c:\\Users\\daled\\anaconda3\\envs\\learn-env\\lib\\site-packages\\keras\\engine\\training.py\", line 1000, in run_step  **\n        outputs = model.train_step(data)\n    File \"c:\\Users\\daled\\anaconda3\\envs\\learn-env\\lib\\site-packages\\keras\\engine\\training.py\", line 864, in train_step\n        return self.compute_metrics(x, y, y_pred, sample_weight)\n    File \"c:\\Users\\daled\\anaconda3\\envs\\learn-env\\lib\\site-packages\\keras\\engine\\training.py\", line 957, in compute_metrics\n        self.compiled_metrics.update_state(y, y_pred, sample_weight)\n    File \"c:\\Users\\daled\\anaconda3\\envs\\learn-env\\lib\\site-packages\\keras\\engine\\compile_utils.py\", line 459, in update_state\n        metric_obj.update_state(y_t, y_p, sample_weight=mask)\n    File \"c:\\Users\\daled\\anaconda3\\envs\\learn-env\\lib\\site-packages\\keras\\utils\\metrics_utils.py\", line 70, in decorated\n        update_op = update_state_fn(*args, **kwargs)\n    File \"c:\\Users\\daled\\anaconda3\\envs\\learn-env\\lib\\site-packages\\keras\\metrics.py\", line 178, in update_state_fn\n        return ag_update_state(*args, **kwargs)\n    File \"c:\\Users\\daled\\anaconda3\\envs\\learn-env\\lib\\site-packages\\keras\\metrics.py\", line 1403, in update_state  **\n        return metrics_utils.update_confusion_matrix_variables(\n    File \"c:\\Users\\daled\\anaconda3\\envs\\learn-env\\lib\\site-packages\\keras\\utils\\metrics_utils.py\", line 619, in update_confusion_matrix_variables\n        y_pred.shape.assert_is_compatible_with(y_true.shape)\n\n    ValueError: Shapes (None, 1007) and (None, 1) are incompatible\n\n"}